using ChainSyncSolution.Domain.Errors;

namespace ChainSyncSolution.ServerApi.Common.Errors;

public class ExceptionHandlingMiddleware
{
    private readonly RequestDelegate _next;

    public ExceptionHandlingMiddleware(RequestDelegate next)
    {
        _next = next;
    }

    public async Task Invoke(HttpContext context)
    {
        try
        {
            await _next(context);
        }
        catch (EmailExistsException ex)
        {
            context.Response.StatusCode = StatusCodes.Status409Conflict;
            await context.Response.WriteAsJsonAsync(new { error = ex.Message });
        }
        catch (Exception ex)
        {
            context.Response.StatusCode = StatusCodes.Status500InternalServerError;
            await context.Response.WriteAsJsonAsync(new { error = "An unexpected error occurred", details = ex.Message });
        }
    }
}
